Workbook

Sheet XMP Inventory P1
A1: Area | B1: Existing screen/flow | C1: Parity required | D1: New shell | E1: Status | F1: Type | G1: Entry point (URL) | H1: Persona | I1: Permission / feature gate | J1: v2 source path | K1: Traffic rank | L1: Notes / Gap
A2: Accounts | B2: Accounts | C2: Yes | D2: ⬜ | E2: Not Started | F2: Page | G2: /admin/accounts | H2: Admin | I2: accessKey: accounts | J2: modules/Accounts/containers | K2: P0
A3: Accounts | B3: Accounts | C3: Yes | D3: ⬜ | E3: Not Started | F3: Page | G3: /user/accounts | H3: User / Agent / Org / Tier | I3: accessKey: accounts | J3: modules/Accounts/containers | K3: P0 | L3: Declared landing route (user DEFAULT_ROUTES.AUTHED_ROUTE).
A4: AgentDashboard | B4: AgentDashboard | C4: Yes | D4: ⬜ | E4: Not Started | F4: Page | G4: /user/account/user-dashboard | H4: User / Agent / Org / Tier | I4: accessKey: dashboard | J4: modules/AgentDashboard/containers | K4: P0 | L4: Declared landing route (user DEFAULT_ROUTES.AGENT_BASE_ROUTE).
A5: AgentReviews | B5: AgentReviews | C5: Yes | D5: ⬜ | E5: Not Started | F5: Page | G5: /user/account/reviews | H5: User / Agent / Org / Tier | I5: accessKey: reviews_management | app: pc_enable_3rd_party_review_mgmt | isForAgent: true | componentId: agent_reviews_management | J5: modules/AgentReviews/containers | K5: P0 | L5: Two intentional entries (agent vs non-agent). Latent bug: both share React key '/account/reviews' when isAgentLogin is true (AuthRouter.js:159).
A6: Auth | B6: AdminSignInPage | C6: Yes | D6: ⬜ | E6: Not Started | F6: Anonymous page | G6: /admin/signin | H6: Admin | I6: Public | J6: modules/Auth/containers/AdminIndex | K6: P0 | L6: Declared landing route (admin DEFAULT_ROUTES.BASE_ROUTE).
A7: Auth | B7: SSOAuth | C7: Yes | D7: ⬜ | E7: Not Started | F7: Page | G7: /sso_callback | H7: All | I7: None (authenticated only) | J7: modules/Auth/containers/SSOAuthIndex | K7: P0
A8: Auth | B8: PrivacyAgreement | C8: Yes | D8: ⬜ | E8: Not Started | F8: Anonymous page | G8: /user/privacy-agreement | H8: User / Agent / Org / Tier | I8: Public | J8: modules/Auth/components/UserSignInSignUp/ThirdPartySignup/PrivacyAgreement | K8: P0 | L8: Declared landing route (user DEFAULT_ROUTES.SSO_LICENSE_ROUTE).
A9: Auth | B9: UserProfileSetup | C9: Yes | D9: ⬜ | E9: Not Started | F9: Page | G9: /user/profile-setup | H9: User / Agent / Org / Tier | I9: None (authenticated only) | J9: modules/Auth/components/UserProfileSetup/containers | K9: P0 | L9: Declared landing route (user DEFAULT_ROUTES.PROFILE_SETUP_ROUTE).
A10: Auth | B10: UserSignIn | C10: Yes | D10: ⬜ | E10: Not Started | F10: Anonymous page | G10: /user/signin | H10: User / Agent / Org / Tier | I10: Public | J10: modules/Auth/components/UserSignInSignUp/SignIn/index.js | K10: P0 | L10: Declared landing route (user DEFAULT_ROUTES.BASE_ROUTE).
A11: Auth | B11: UserSignInPage | C11: Yes | D11: ⬜ | E11: Not Started | F11: Anonymous page | G11: /xpa/signin | H11: XPA | I11: Public | J11: modules/Auth/containers/UserIndex | K11: P0 | L11: Declared landing route (xpa DEFAULT_ROUTES.BASE_ROUTE).
A12: Hierarchy | B12: Hierarchy | C12: Yes | D12: ⬜ | E12: Not Started | F12: Page | G12: /admin/account/hierarchy | H12: Admin | I12: accessKey: hierarchy | J12: modules/Hierarchy/containers | K12: P0 | L12: Declared landing route (admin DEFAULT_ROUTES.CONTEXT_SELECTED_ROUTE).
A13: Hierarchy | B13: Hierarchy | C13: Yes | D13: ⬜ | E13: Not Started | F13: Page | G13: /user/account/hierarchy | H13: User / Agent / Org / Tier | I13: accessKey: hierarchy | J13: ../../modules/Hierarchy/containers | K13: P0
A14: Hierarchy | B14: Hierarchy | C14: Yes | D14: ⬜ | E14: Not Started | F14: Page | G14: /user/account/hierarchy/:id | H14: User / Agent / Org / Tier | I14: accessKey: hierarchy | J14: ../../modules/Hierarchy/containers | K14: P0
A15: HierarchyDashboards | B15: HierarchyDashboards | C15: Yes | D15: ⬜ | E15: Not Started | F15: Page | G15: /admin/account/dashboard | H15: Admin | I15: accessKey: dashboard | J15: modules/HierarchyDashboards/containers | K15: P0 | L15: Declared landing route (admin DEFAULT_ROUTES.DASHBOARD_ROUTE).
A16: HierarchyDashboards | B16: HierarchyDashboards | C16: Yes | D16: ⬜ | E16: Not Started | F16: Page | G16: /user/account/dashboard | H16: User / Agent / Org / Tier | I16: accessKey: dashboard | J16: modules/HierarchyDashboards/containers | K16: P0 | L16: Declared landing route (user DEFAULT_ROUTES.TIER_BASE_ROUTE).
A17: Listing | B17: ListingCustomerDashboard | C17: Yes | D17: ⬜ | E17: Not Started | F17: Page | G17: /user/account/listing/dashboard | H17: User / Agent / Org / Tier | I17: accessKey: listings | app: pc_enable_listings | J17: modules/Listing/submodules/CustomerListingDashboard/container | K17: P0 | L17: Declared landing route (user DEFAULT_ROUTES.LISTING_MGR_BASE_ROUTE).
A18: Nav | B18: Nav (left menu + header chrome) | C18: Yes | D18: ⬜ | E18: Not Started | F18: Global chrome | G18: n/a - mounted by AuthRouter.js:8 | H18: All | I18: getAccess() per item | J18: modules/Nav | K18: P0 | L18: 247 nav path entries across admin/user/agent. Permission gating lives here as well as in AuthPage - port as ONE concept.
A19: Organizations | B19: Organizations | C19: Yes | D19: ⬜ | E19: Not Started | F19: Page | G19: /admin/organizations | H19: Admin | I19: accessKey: organizations | J19: modules/Organizations/containers | K19: P0 | L19: Declared landing route (admin DEFAULT_ROUTES.AUTHED_ROUTE - admins land HERE, not on /accounts).
A20: Organizations | B20: Organizations | C20: Yes | D20: ⬜ | E20: Not Started | F20: Page | G20: /user/organizations | H20: User / Agent / Org / Tier | I20: accessKey: organizations | J20: modules/Organizations/containers | K20: P0 | L20: Declared landing route (user DEFAULT_ROUTES.CONTEXT_SELECTED_ROUTE).
A21: Page | B21: Page shell / layout | C21: Yes | D21: ⬜ | E21: Not Started | F21: Global chrome | G21: n/a - mounted by AuthPage.js | H21: All | I21: n/a | J21: modules/Page | K21: P0 | L21: Page header, breadcrumbs, side panel host.
A22: Reviews | B22: Reviews | C22: Yes | D22: ⬜ | E22: Not Started | F22: Page | G22: /admin/account/reviews | H22: Admin | I22: accessKey: reviews_management | app: pc_enable_3rd_party_review_mgmt | J22: modules/Reviews/containers | K22: P0
A23: Reviews | B23: Reviews | C23: Yes | D23: ⬜ | E23: Not Started | F23: Page | G23: /user/account/reviews | H23: User / Agent / Org / Tier | I23: accessKey: reviews_management | app: pc_enable_3rd_party_review_mgmt | isForAgent: false | J23: modules/Reviews/containers | K23: P0 | L23: Two intentional entries (agent vs non-agent). Latent bug: both share React key '/account/reviews' when isAgentLogin is true (AuthRouter.js:159).
A24: Settings | B24: Settings | C24: Yes | D24: ⬜ | E24: Not Started | F24: Page | G24: /admin/account/settings | H24: Admin | I24: accessKey: settings | J24: modules/Settings/containers | K24: P0
A25: Settings | B25: Settings | C25: Yes | D25: ⬜ | E25: Not Started | F25: Page | G25: /user/account/settings | H25: User / Agent / Org / Tier | I25: accessKey: settings | J25: modules/Settings/containers | K25: P0
A26: UserManagement | B26: UserDetails | C26: Yes | D26: ⬜ | E26: Not Started | F26: Page | G26: /admin/individualprofessionals/manageusers | H26: Admin | I26: accessKey: user_management | J26: modules/UserManagement/components/UserDetails | K26: P0 | L26: Declared landing route (admin DEFAULT_ROUTES.INDIVIDUAL_PROFESSIONALS_ROUTE).
A27: AccountSettings | B27: Account | C27: No - dead | D27: ⬜ | E27: Excluded | F27: Page | G27: /admin/account | H27: Admin | I27: None (authenticated only) | J27: modules/AccountSettings/containers | K27: P1 | L27: Renders the AccountSettings drawer container with no showAccountSetting prop - blank page.
A28: AccountSettings | B28: Account | C28: No - dead | D28: ⬜ | E28: Excluded | F28: Page | G28: /user/account | H28: User / Agent / Org / Tier | I28: None (authenticated only) | J28: modules/AccountSettings/containers | K28: P1 | L28: Renders the AccountSettings drawer container with no showAccountSetting prop - blank page.
A29: Admins | B29: AdminActivityFeed | C29: Yes | D29: ⬜ | E29: Not Started | F29: Page | G29: /admin/activityfeed | H29: Admin | I29: accessKey: admins | J29: modules/Admins/components/ActivityFeed/containers | K29: P1
A30: Admins | B30: Admins | C30: Yes | D30: ⬜ | E30: Not Started | F30: Page | G30: /admin/adminslist | H30: Admin | I30: accessKey: admins | J30: modules/Admins/containers | K30: P1
A31: AppSettings | B31: AppSettings | C31: Yes | D31: ⬜ | E31: Not Started | F31: Page | G31: /admin/settings | H31: Admin | I31: accessKey: admin_settings | J31: modules/AppSettings | K31: P1
A32: AppSettings | B32: AssetManagement | C32: Yes | D32: ⬜ | E32: Not Started | F32: Page | G32: /admin/settings/assetmanagement | H32: Admin | I32: accessKey: admin_settings | J32: modules/AppSettings/components/AssetManagement | K32: P1
A33: AppSettings | B33: BannerManagement | C33: Yes | D33: ⬜ | E33: Not Started | F33: Page | G33: /admin/settings/banners | H33: Admin | I33: accessKey: admin_settings | J33: modules/AppSettings/components/BannerManagement | K33: P1
A34: AppSettings | B34: BannerManagement | C34: Yes | D34: ⬜ | E34: Not Started | F34: Page | G34: /admin/settings/banners/edit_template | H34: Admin | I34: accessKey: admin_settings | J34: modules/AppSettings/components/BannerManagement | K34: P1
A35: AppSettings | B35: BannerManagement | C35: Yes | D35: ⬜ | E35: Not Started | F35: Page | G35: /admin/settings/banners/impressions | H35: Admin | I35: accessKey: admin_settings | J35: modules/AppSettings/components/BannerManagement | K35: P1
A36: AppSettings | B36: CampaignTemplates | C36: Yes | D36: ⬜ | E36: Not Started | F36: Page | G36: /admin/settings/campaigntemplates | H36: Admin | I36: accessKey: admin_settings | J36: modules/AppSettings/components/CampaignTemplates | K36: P1
A37: AppSettings | B37: TemplateEditor | C37: No - other discipline | D37: ⬜ | E37: Excluded | F37: Page | G37: /admin/settings/campaigntemplates/templateseditor | H37: Admin | I37: accessKey: admin_settings | J37: modules/AppSettings/components/TemplateEditor | K37: P1 | L37: Campaigns editor internals belong to the Campaigns discipline (deck slide 13). XMP ports the Campaigns list only.
A38: AppSettings | B38: EmailDeliveryDomain | C38: Yes | D38: ⬜ | E38: Not Started | F38: Page | G38: /admin/settings/customfromemails-deliverydomains | H38: Admin | I38: accessKey: admin_settings | J38: modules/AppSettings/components/EmailDeliveryDomain | K38: P1
A39: AppSettings | B39: EngagementApp | C39: Yes | D39: ⬜ | E39: Not Started | F39: Page | G39: /admin/settings/engagement | H39: Admin | I39: accessKey: admin_settings | J39: modules/AppSettings/components/EngagementApp | K39: P1
A40: AppSettings | B40: EmailServiceProvider | C40: Yes | D40: ⬜ | E40: Not Started | F40: Page | G40: /admin/settings/engagement/emailserviceprovider | H40: Admin | I40: accessKey: admin_settings | J40: modules/AppSettings/components/EngagementApp/components/EmailServiceProvider | K40: P1
...

Sheet Area Summary
A1: Sizing view - route count does not track effort; lines and drawers do
A3: Area | B3: Route entries | C3: Traffic rank | D3: Parity rows | E3: Excluded rows | F3: Files | G3: Lines | H3: Drawers | I3: Modals | J3: Sizing note
A4: (routes infra: PageNotFound) | B4: 4 | C4: P2 | D4: 4 | E4: 0
A5: (shared components) | B5: 2 | C5: P2 | D5: 2 | E5: 0
A6: AIVisibility | B6: 1 | C6: P2 | D6: 1 | E6: 0 | F6: 23 | G6: 4546 | H6: 0 | I6: 0
A7: AbusiveReviews | B7: 1 | C7: P2 | D7: 1 | E7: 0 | F7: 11 | G7: 1886 | H7: 0 | I7: 0
A8: AccountSettings | B8: 2 | C8: P1 | D8: 0 | E8: 2 | F8: 30 | G8: 5633 | H8: 3 | I8: 0
A9: Accounts | B9: 2 | C9: P0 | D9: 2 | E9: 0 | F9: 43 | G9: 6550 | H9: 7 | I9: 2
A10: AdminGroups | B10: 1 | C10: P2 | D10: 1 | E10: 0 | F10: 10 | G10: 979 | H10: 0 | I10: 0
A11: Admins | B11: 2 | C11: P1 | D11: 2 | E11: 0 | F11: 19 | G11: 3014 | H11: 0 | I11: 0
A12: AgentDashboard | B12: 2 | C12: P0 | D12: 2 | E12: 0 | F12: 210 | G12: 32491 | H12: 2 | I12: 2
A13: AgentReviews | B13: 1 | C13: P0 | D13: 1 | E13: 0 | F13: 9 | G13: 1352 | H13: 0 | I13: 0
A14: AgentSettings | B14: 1 | C14: P2 | D14: 1 | E14: 0 | F14: 48 | G14: 8131 | H14: 1 | I14: 1
A15: AppSettings | B15: 16 | C15: P1 | D15: 15 | E15: 1 | F15: 194 | G15: 25662 | H15: 18 | I15: 2
A16: Auth | B16: 35 | C16: P0 | D16: 35 | E16: 0 | F16: 235 | G16: 47266 | H16: 1 | I16: 2 | J16: Very large - budget by lines and drawers, not by route count.
A17: Bundles | B17: 2 | C17: P1 | D17: 2 | E17: 0 | F17: 30 | G17: 2339 | H17: 1 | I17: 1
A18: Campaigns | B18: 13 | C18: P1 | D18: 4 | E18: 9 | F18: 669 | G18: 73974 | H18: 18 | I18: 2 | J18: Very large - budget by lines and drawers, not by route count.
A19: ChatBot | B19: 0 | C19: P2 | D19: 1 | E19: 0 | F19: 13 | G19: 1985 | H19: 0 | I19: 0
A20: DataAndAnalysis | B20: 4 | C20: P1 | D20: 4 | E20: 0 | F20: 33 | G20: 8207 | H20: 4 | I20: 2
A21: GlobalDrawer | B21: 0 | C21: P1 | D21: 1 | E21: 0 | F21: 6 | G21: 365 | H21: 1 | I21: 0
A22: Hierarchy | B22: 3 | C22: P0 | D22: 3 | E22: 0 | F22: 373 | G22: 81271 | H22: 45 | I22: 3 | J22: Very large - budget by lines and drawers, not by route count.
A23: HierarchyDashboards | B23: 6 | C23: P0 | D23: 6 | E23: 0 | F23: 90 | G23: 10496 | H23: 0 | I23: 2
A24: IncompleteSurvey | B24: 8 | C24: P2 | D24: 6 | E24: 2 | F24: 22 | G24: 3798 | H24: 0 | I24: 1
A25: Insights | B25: 1 | C25: P2 | D25: 1 | E25: 0 | F25: 76 | G25: 9010 | H25: 1 | I25: 0
A26: Integrations | B26: 1 | C26: P1 | D26: 1 | E26: 0 | F26: 5 | G26: 643 | H26: 0 | I26: 0
A27: LeaderBoard | B27: 2 | C27: P1 | D27: 2 | E27: 0 | F27: 23 | G27: 3519 | H27: 0 | I27: 0
A28: LearningCenter | B28: 2 | C28: P2 | D28: 2 | E28: 0 | F28: 12 | G28: 2065 | H28: 1 | I28: 0
A29: Listing | B29: 20 | C29: P0 | D29: 20 | E29: 0 | F29: 230 | G29: 28986 | H29: 7 | I29: 1
A30: Listings | B30: 3 | C30: P1 | D30: 3 | E30: 0 | F30: 180 | G30: 26469 | H30: 7 | I30: 1
A31: Mismatches | B31: 2 | C31: P1 | D31: 2 | E31: 0 | F31: 63 | G31: 8785 | H31: 5 | I31: 1
A32: Nav | B32: 0 | C32: P0 | D32: 1 | E32: 0 | F32: 97 | G32: 11458 | H32: 0 | I32: 0
A33: NoConnectionFound | B33: 2 | C33: P2 | D33: 2 | E33: 0 | F33: 1 | G33: 77 | H33: 0 | I33: 0
A34: Notifications | B34: 4 | C34: P1 | D34: 4 | E34: 0 | F34: 9 | G34: 997 | H34: 0 | I34: 0
... A39: ProductGuide | B39: 0 | C39: P2 | D39: 1 | E39: 0 | F39: 15 | G39: 2879 | H39: 1 | I39: 1
A40: Profile | B40: 8 | C40: P1 | D40: 6 | E40: 2 | F40: 288 | G40: 48520 | H40: 12 | I40: 4 | J40: Very large - budget by lines and drawers, not by route count.
A41: ProfileEnhancement | B41: 8 | C41: P1 | D41: 8 | E41: 0 | F41: 160 | G41: 41165 | H41: 1 | I41: 0 | J41: Very large - budget by lines and drawers, not by route count.
A42: PromotePartners | B42: 1 | C42: P2 | D42: 1 | E42: 0 | F42: 50 | G42: 6536 | H42: 2 | I42: 0
A43: Referrals | B43: 1 | C43: P2 | D43: 1 | E43: 0 | F43: 54 | G43: 8654 | H43: 2 | I43: 1
A44: Reports | B44: 12 | C44: P1 | D44: 12 | E44: 0 | F44: 71 | G44: 14427 | H44: 0 | I44: 0
A45: RequestReview | B45: 1 | C45: P1 | D45: 1 | E45: 0 | F45: 38 | G45: 6317 | H45: 3 | I45: 0
...

Sheet Gaps & Decisions
A1: Gaps found while taking the inventory - written down now rather than discovered later
A3: ID | B3: Finding | C3: Evidence | D3: Type | E3: Recommendation | F3: Decision | G3: Decided By | H3: Date
A4: XMP-01 | B4: Full parity across XMP is not reachable in the window | C4: 240 route entries / 43 areas / 220 drawer mount points / 677,148 lines | D4: Scope | E4: Read the card as inventory + top-traffic parity + written gap log. Confirm the bar with Geetha.
A5: XMP-02 | B5: No traffic data available, yet the brief says sequence by traffic | C5: No analytics access; ranking derived from DEFAULT_ROUTES in admin.js:126-127 and user.js:108-113 | D5: Assumption | E5: Treat the P0/P1/P2 column as an assumption. Get Geetha to correct the order before the build starts.
A6: XMP-03 | B6: The new shell is not available on this machine | C6: No tailwind/shadcn/supabase/postgres anywhere; deck slide 16 says the shells exist and are wired | D6: Blocker | E6: Build a local stand-in on the same stack; escalate for real shell access by 20 Sept.
A7: XMP-04 | B7: Agent-assisted campaigns and graph audiences are a different discipline | C7: Deck slide 13 (Campaigns) vs slide 12 (XMP); intake lists Graph as OFF LIMITS | D7: Scope | E7: Port the Campaigns LIST for navigational parity; leave editor, settings and audience to that owner.
A8: XMP-05 | B8: SocialMonitor is entirely unreachable but still shipped | C8: 46 files / 7,375 lines / 11 drawers; no route, no component importer; nav link at Nav/userNavItems.js:1345 | D8: Dead code | E8: Exclude from parity. Confirm with Geetha that no customer reaches it before deleting.
A9: XMP-06 | B9: Testimonials widget config is advertised in nav but has no route | C9: nav path /account/widget/testimonials/configuration; modules/Widgets/submodules/Testimonials | D9: Dead code | E9: Exclude from parity; confirm it is not a capability users lost silently.
A10: XMP-07 | B10: Two route entries embed a query string and can never match | C10: '/account/incompletesurvey?campaignId' in admin.js:585 and user.js:726 | D10: Dead route | E10: Do not port. React Router v5 matches pathname only.
A11: XMP-08 | B11: /account/hierarchy/preview is declared twice per persona file | C11: admin.js:368 and :372; user.js:321 and :346 | D11: Duplicate | E11: Port once. The second entry is unreachable under <Switch>.
A12: XMP-09 | B12: /admin/account and /user/account render a blank page | C12: admin.js:169, user.js:261 - AccountSettings container with no showAccountSetting prop | D12: Dead route | E12: Do not port the route.
A13: XMP-10 | B13: Six nav paths point at URLs with no route, falling through to PageNotFound | C13: socialmonitor (x2), testimonials config (x2), /admin/listing, /admin/tableaumetrics | D13: Bug | E13: Fix in the port by deriving nav from the route table instead of a parallel hand-maintained list.
A14: XMP-11 | B14: Duplicate React key when an agent loads /user/account/reviews | C14: user.js:275-283 and :284-290 both keyed by routePath at AuthRouter.js:159 | D14: Bug | E14: Report upstream to the v2 team; key by componentId in the port.
A15: XMP-12 | B15: Permission gating is implemented twice and can disagree | C15: routes/components/AuthPage.js (accessKey/app/feature) and Nav/components/index.js getAccess() | D15: Architecture | E15: Port as ONE permission concept consumed by both router and nav.
... A17: XMP-14 | B17: Tabs and drawers are invisible to a route census | C17: 0 nested <Route>; 220 drawer mounts; query-string tab states such as /account/insights?tab=Score | D17: Method | E17: Pass 2 must inventory in-screen states for P0 areas or the screen count stays understated.

Sheet Progress & Legend
A1: XMP parity - pass 1 progress
A2: Live formulas over the 'XMP Inventory P1' tab. Update Status there; this updates itself.
A4: Headline
A5: Rows inventoried | B5: =COUNTA('XMP Inventory P1'!$A$2:$A$248)
A6: In parity scope | B6: =COUNTIF('XMP Inventory P1'!$C$2:$C$248,"Yes")
A7: Excluded (with a written reason) | B7: =COUNTIF('XMP Inventory P1'!$E$2:$E$248,"Excluded")
A8: Done | B8: =COUNTIF('XMP Inventory P1'!$E$2:$E$248,"Done")
A9: % complete (of parity scope) | B9: =IFERROR(COUNTIF('XMP Inventory P1'!$E$2:$E$248,"Done")/COUNTIF('XMP Inventory P1'!$C$2:$C$248,"Yes"),0)
A10: P0 rows not yet Done | B10: =COUNTIFS('XMP Inventory P1'!$K$2:$K$248,"P0",'XMP Inventory P1'!$E$2:$E$248,"<>Done")
A11: Open gaps awaiting a decision | B11: =COUNTBLANK('Gaps & Decisions'!$F$4:$F$17)
A13: By Status | B13: Count | C13: % of all
A14: Not Started | B14: =COUNTIF('XMP Inventory P1'!$E$2:$E$248,$A$14) | C14: =IFERROR(B14/$B$5,0)
A15: In Progress | B15: =COUNTIF('XMP Inventory P1'!$E$2:$E$248,$A$15) | C15: =IFERROR(B15/$B$5,0)
A16: In Review | B16: =COUNTIF('XMP Inventory P1'!$E$2:$E$248,$A$16) | C16: =IFERROR(B16/$B$5,0)
A17: Done | B17: =COUNTIF('XMP Inventory P1'!$E$2:$E$248,$A$17) | C17: =IFERROR(B17/$B$5,0)
A18: Blocked | B18: =COUNTIF('XMP Inventory P1'!$E$2:$E$248,$A$18) | C18: =IFERROR(B18/$B$5,0)
A19: Excluded | B19: =COUNTIF('XMP Inventory P1'!$E$2:$E$248,$A$19) | C19: =IFERROR(B19/$B$5,0)
A21: By Traffic rank | B21: Rows | C21: Not Done
A22: P0 | B22: =COUNTIF('XMP Inventory P1'!$K$2:$K$248,$A$22) | C22: =COUNTIFS('XMP Inventory P1'!$K$2:$K$248,$A$22,'XMP Inventory P1'!$E$2:$E$248,"<>Done")
A23: P1 | B23: =COUNTIF('XMP Inventory P1'!$K$2:$K$248,$A$23) | C23: =COUNTIFS('XMP Inventory P1'!$K$2:$K$248,$A$23,'XMP Inventory P1'!$E$2:$E$248,"<>Done")
A24: P2 | B24: =COUNTIF('XMP Inventory P1'!$K$2:$K$248,$A$24) | C24: =COUNTIFS('XMP Inventory P1'!$K$2:$K$248,$A$24,'XMP Inventory P1'!$E$2:$E$248,"<>Done")
A26: Counted facts (cross-checked twice)
A27: Route entries in src/routes/config | B27: 240
A28: Distinct full URLs (with persona prefix) | B28: 237
A29: Distinct routePath strings | B29: 157
A30: Areas | B30: 43
A31: Drawer mount points / modals | B31: 220 / 34
A32: Module files / lines | B32: 4,382 / 677,148
A33: Nested <Route> declarations | B33: 0 - tabs and drawers are state-driven
A35: Legend
A36: Parity required
A37: Yes | D37: Must exist on the new shell at capability parity.
A38: No - dead | D38: Unreachable in today's XMP. Excluded, with the evidence on the Gaps tab.
A39: No - duplicate | D39: A second declaration of a screen already counted.
A40: No - other discipline | D40: Owned by another builder (Campaigns editor internals, slide 13).
A42: Traffic rank
A43: P0 | D43: Persona landing routes, sign-in, and global chrome. Build first.
A44: P1 | D44: Regular multi-persona use.
A45: P2 | D45: Deep leaf screens, niche auth flows, rare or single-persona admin.
A47: How the rank was derived
...
