Workbook

Sheet Accounts Inventory
A1: ID | B1: Type | C1: Item | D1: Entry Point | E1: v2 Source Path | F1: What The User Does | G1: Key UI Elements | H1: API Endpoint(s) | I1: Permission / Role Gate | J1: Traffic Priority | K1: Port Decision | L1: Status | M1: Owner | N1: Target | O1: Notes / Gaps
A2: ACC-01 | B2: Screen | C2: Accounts List | D2: /admin/accounts | /user/accounts Nav: 'Accounts'. Also the user-persona post-login landing when the user belongs to >1 account. | E2: src/modules/Accounts/containers/index.js src/modules/Accounts/components/index.js | F2: Browse, search and filter every account the user can see; switch the app's account context (enter an account); run per-account lifecycle actions. | G2: Composed of 4 regions: header band, filter side panel, table, row action menu. | H2: GET /v2/core/accounts?page&limit&key&my_account&new_account_flag&sort_by&order&status&org_id&users | I2: Route accessKey 'accounts', checked against userPermission.nav_menu_list in routes/components/AuthPage.js | J2: P0 | K2: Port as-is | L2: Not Started | M2: The ONLY screen in the module. No nested routes and no AntD Tabs anywhere in modules/Accounts.
A3: ACC-02 | B3: Region | C3: Header band | D3: Top of the Accounts List screen | E3: src/modules/Accounts/components/AccountsHeader/index.js | F3: Switch between the three list modes, open the advanced filter panel, start a new account. | G3: Segmented Button.Group used as de-facto tabs: New Accounts (my_account=0) / My Accounts (=1, default) / All Accounts (=2). Deactivation alert banner 'N Account has requested deactivation'. Advanced-filter toggle. 'New Account' button. Suspended-account message. | H3: Drives the my_account / new_account_flag params on the list endpoint | I3: Whole group only for isSuperAdmin || isOnboardingAdmin || isCSAdmin || isOnlyXPAAdmin. 'All Accounts' hidden for isOnlyXPAAdmin. Banner needs isSuperAdmin===1 && deactivationRequestCount. 'New Account' needs userPermission.account includes 'create'. | J3: P0 | K3: Redesign | L3: Not Started | M3: Button.Group is doing a tab's job. On the new shell make it a real segmented control / tabs.
A4: ACC-03 | B4: Region | C4: Filter side panel | D4: Advanced-filter toggle in the header band | E4: src/modules/Accounts/components/AccountsSearchFilter/index.js src/modules/Accounts/components/AccountsSearchFilter/InfiniteScrollDropdown.js src/modules/Accounts/components/AccountsSearchFilter/DropdownOptions.js | F4: Narrow the account list by free text, organization, status and username. | G4: Rendered in SidePanelCard titled 'Filter Accounts' with a global Clear. Search (debounced 800ms, placeholder 'E.g: California'). Organization: paginated infinite-scroll dropdown. Status: multi-select. Username: debounced search. | H4: GET /v2/core/organizations/get_organizations?key&status=0,1&limit=300&type=accounts_filter | I4: Organization filter: isAdmin only. Username filter: isAdmin && currentRole !== 'Sales Admin'. | J4: P0 | K4: Port as-is | L4: Not Started | M4: Status values are raw numeric codes: Active=1, Inactive=-1, Deactivation requested=3, Onboarding=0, Suspended=-3. Map these explicitly on the new shell.
A5: ACC-04 | B5: Region | C5: Accounts table | D5: Body of the Accounts List screen | E5: src/modules/Accounts/components/AccountsList/index.js src/modules/Accounts/components/AccountsList/partials/OnboardingInfo.js src/modules/Accounts/components/AccountsList/partials/MismatchCount.js | F5: Read account state at a glance, enter an account, jump to that account's mismatches. | G5: AntD Table id='accountslist_table'. 7 columns: Accounts (name link enters the account; sortable; EX tag for exception accounts; deactivation icon for superadmin on status 3), Tiers, Users, Info (Onboarding badge + Mismatches badge), Activated On (sortable), Status (sortable), Action. Footer: Pagination + page-size dropdown, shown only when accountCount > 10. No row selection. | H5: Same list endpoint; sorting via sort_by & order params | I5: Tier Managers cannot open suspended accounts - the name renders as plain text and View is disabled. | J5: P0 | K5: Port as-is | L5: Not Started | M5: No bulk actions and no export exist anywhere in this module - see GAP-09 before assuming that is intentional.
A6: ACC-05 | B6: Region | C6: Row action menu | D6: 'Action' column on each table row | E6: src/modules/Accounts/components/AccountsList/partials/ActionItem.js | F6: Run per-account admin lifecycle actions. | G6: 11 permission-gated items: Account Settings, Mark as Exception, Remove as Exception, Configure Bundles, Configure Products, Duplicate Account, Assign Manager, Edit Account, Suspend Account, Reactivate Account, Activate. For status===3 the row shows a single Accept/Reject button instead of the menu. | H6: Each item dispatches its own call - see the drawer rows below | I6: Per item, from userPermission.account: setting, mark_exception, remove_exception, bundles, duplicate, activate, activate_onboarding; plus editPermission and isSuperAdmin. Every item is disabled when !isSuperAdmin && item.status===-3. | J6: P0 | K6: Redesign | L6: Not Started | M6: 11 gated items behind one dropdown. Parity of capability, not layout - split into inline primary actions plus an overflow menu (GAP-12).
A7: ACC-06 | B7: Drawer | C7: New Account | D7: 'New Account' button in the header band (id=newaccount_drawer) | E7: src/modules/Accounts/components/AccountsHeader/partials/NewAccountDrawer.js src/modules/Accounts/components/AccountsHeader/partials/NewAccount.js | F7: Create a new account. | G7: Fields: account name, Vertical, category, Products & Services (ServicesDropdown), Blueprint, Organization, Country, Time Zone (options depend on Country), Date Format (auto-derived). | H7: POST /v2/core/accounts GET /v2/core/verticals?key&limit=2000&source=UI GET /v2/prl/country | I7: userPermission.account includes 'create' | J7: P0 | K7: Port as-is | L7: Not Started | M7: Time Zone list is dependent on the selected Country - keep that dependency on the new shell.
A8: ACC-07 | B8: Inline section | C8: New Account > Create New Organization | D8: 'Create New' option inside the Organization dropdown of ACC-06 | E8: src/modules/Accounts/components/AccountsHeader/partials/NewAccountOrg.js | F8: Create an organization inline without leaving the new-account flow. | G8: Fields: organization name, contact name, contact email, contact number, Onboarding Owner. | H8: Submitted as part of the POST /v2/core/accounts payload | I8: isSuperAdmin || isOnboardingAdmin. Hidden in duplicate mode. Entire block skipped for isOrgManager. | J8: P1 | K8: Port as-is | L8: Not Started | M8: Nested creation inside a creation form - verify this is still wanted before reproducing it.
A9: ACC-08 | B9: Inline section | C9: New Account > Add New Manager | D9: Toggle inside the ACC-06 drawer body | E9: src/modules/Accounts/components/AccountsHeader/partials/NewAccount.js | F9: Create the account's first manager inline. | G9: Fields: first name, last name, email, phone (country-aware validation). | H9: POST /v2/core/users | I9: Inherits the ACC-06 'create' gate | J9: P1 | K9: Port as-is | L9: Not Started | M9: Phone validation is country-aware via react-international-phone + libphonenumber-js.
A10: ACC-09 | B10: Drawer | C10: Duplicate Account | D10: Row action menu > Duplicate Account (id=duplicateaccount_drawer) | E10: src/modules/Accounts/components/AccountsHeader/partials/NewAccountDrawer.js (duplicate mode) | F10: Clone an existing account's configuration into a new account. | G10: Same form as ACC-06; the title and several fields switch to read-only duplicate mode and prefill from selectedAccountInfo. | H10: GET /v2/core/accounts/{accountId} POST /v2/core/accounts | I10: userPermission.account includes 'duplicate' | J10: P1 | K10: Port as-is | L10: Not Started | M10: Same component as ACC-06 in a different mode - port once with two modes, do not build twice.
A11: ACC-10 | B11: Drawer | C11: Edit Account | D11: Row action menu > Edit Account (id=accountedit_drawer) | E11: src/modules/Accounts/components/AccountsList/partials/EditAccount.js | F11: Edit an existing account's core attributes. | G11: Fields: Name, Vertical, category, services, Blueprint (disabled), Country (disabled), Time Zone (enabled only for superadmin), Date Format (disabled). Vertical and category are locked when the account is Finance > Bank. | H11: GET /v2/core/accounts/{accountId} PUT /v2/core/accounts/{accountId} | I11: editPermission || currentRole === 'Organization Manager', and item.status !== 1 | J11: P0 | K11: Redesign | L11: Not Started | M11: 4 of 7 fields are permanently disabled - a bad screen to reproduce faithfully. See GAP-10.
A12: ACC-11 | B12: Drawer | C12: Activate Account | D12: Row action menu > Activate (id=accountactivation_drawer) | E12: src/modules/Accounts/components/AccountsList/partials/ActivateAdminAccount.js | F12: Confirm activation of an onboarding or inactive account. | G12: Confirmation dialog; on confirm calls AccountStatus({status: 1}). | H12: PUT /v2/core/accounts/{id}/activate | I12: (activate || activate_onboarding) + item.status is 0 or -1 | J12: P1 | K12: Redesign | L12: Not Started | M12: Duplicate capability with ACC-12 reached by a different route - collapse the two (GAP-08).
A13: ACC-12 | B13: Drawer | C13: Account Status - Onboarding | D13: 'Onboarding' badge in the table's Info column | E13: src/modules/Accounts/components/index.js:389-415 src/modules/Accounts/components/AccountsList/partials/ActivateAccount.js | F13: A second, separate activate flow for onboarding accounts. | G13: Drawer titled 'Account Status - Onboarding' with Cancel / Activate footer. | H13: PUT /v2/core/accounts/{id}/activate | I13: canActivateOnboardingAccount (userPermission.account includes 'activate_onboarding') | J13: P1 | K13: Redesign | L13: Not Started | M13: Same outcome as ACC-11 via a different entry point and a different component. Merge on the new shell.
... A25: ACC-24 | B25: Dead code | C25: SyncStatus.js (orphan file) | D25: NONE - file is never imported | E25: src/modules/Accounts/components/AccountsList/partials/SyncStatus.js | F25: Was: the 'Not Synced' badge button that opened the Sync to V1 drawer. | G25: 27 lines, unreferenced. | H25: n/a | I25: n/a | J25: P2 | K25: Drop | L25: Excluded | M25: VERIFIED DEAD: zero imports repo-wide. Removing this is what stranded ACC-20. See GAP-05.

Sheet Gaps & Decisions
A1: Gaps found while taking the inventory - written down now rather than discovered later
A3: ID | B3: Finding | C3: Evidence (file:line) | D3: Type | E3: Recommendation | F3: Decision | G3: Decided By | H3: Date
A4: GAP-01 | B4: Sync to V1 drawer is rendered on every page load but has no reachable trigger | C4: src/modules/Accounts/components/index.js:354-388 vs src/modules/Accounts/components/AccountsList/index.js:95,98 | D4: Dead code | E4: Do not port. Also remove the syncToV1 / updateSyncStatus actions and their reducer state, which are still wired.
A5: GAP-02 | B5: Assign Admin ('Customer Success Admin') modal can never open | C5: src/modules/Accounts/components/AccountsList/partials/ActionItem.js:361 vs :40-64 | D5: Dead code | E5: Do not port. Confirm with Geetha that CS-Admin assignment is not a capability users lost silently.
A6: GAP-03 | B6: Deactivate Account drawer can never open | C6: src/modules/Accounts/components/AccountsList/partials/ActionItem.js:374 vs :40-64 | D6: Dead code | E6: Do not port. Deactivation is handled by the request/approve flow (ACC-13).
A7: GAP-04 | B7: ManagerAssign.js is an orphan - zero imports repo-wide | C7: src/modules/Accounts/components/AccountsList/partials/ManagerAssign.js | D7: Dead code | E7: Do not port. Superseded by AssignManagerModal.js.
A8: GAP-05 | B8: SyncStatus.js is an orphan - zero imports repo-wide | C8: src/modules/Accounts/components/AccountsList/partials/SyncStatus.js | D8: Dead code | E8: Do not port. Its removal is what stranded the Sync to V1 drawer.
A9: GAP-06 | B9: /admin/account and /user/account (singular) render a blank page | C9: src/routes/config/admin.js:169 | src/routes/config/user.js:261 | D9: Dead route | E9: Do not port the route. It maps to the AccountSettings drawer container with no showAccountSetting prop, so it renders an empty fragment.
A10: GAP-07 | B10: /user/accounts is declared twice in the nav as 'Accounts' and 'Org Accounts' | C10: src/modules/Nav/userNavItems.js:105 and :116; resolved at Nav/components/index.js:992-1013 | D10: Duplicate | E10: Ship one nav entry with a role-dependent label instead of two entries competing for the same path.
A11: GAP-08 | B11: Two separate activate flows exist for the same outcome | C11: ActivateAdminAccount.js (row menu) vs ActivateAccount.js via src/modules/Accounts/components/index.js:389-415 (Onboarding badge) | D11: Redesign | E11: Collapse into a single activate flow with one entry point. Parity of capability, not of layout.
A12: GAP-09 | B12: The module has no bulk actions and no export anywhere | C12: Whole module - src/modules/Accounts/components/AccountsList/index.js has no row selection | D12: Product decision | E12: Confirm this is intentional. For the largest-inventory product this looks like a capability gap worth closing during the port, not a parity item to preserve.
A13: GAP-10 | B13: Edit Account shows 7 fields of which 4 are permanently disabled | C13: src/modules/Accounts/components/AccountsList/partials/EditAccount.js | D13: Redesign | E13: Either make Blueprint / Country / Date Format editable, or stop rendering them as dead inputs. Reproducing this faithfully is the failure mode named in the brief.
A14: GAP-11 | B14: Accounts style and partial files are imported by other modules | C14: Imported by Organizations, UserManagement, Profile, Hierarchy and Settings | D14: Constraint | E14: Do not delete Accounts files when the module is ported. Shared pieces must be extracted first or those modules break.
A15: GAP-12 | B15: Row action menu carries 11 permission-gated items in a single dropdown | C15: src/modules/Accounts/components/AccountsList/partials/ActionItem.js | D15: Redesign | E15: Split into 2-3 inline primary actions plus an overflow menu. Decide the primary set from traffic data.

Sheet Progress & Legend
A1: XMP Port - Accounts Module Progress
A2: All figures are live formulas over the 'Accounts Inventory' tab. Update Status there; this updates itself.
A4: Headline
A5: Total items inventoried | B5: =COUNTA('Accounts Inventory'!$A$2:$A$25)
A6: In scope (excludes Excluded) | B6: =COUNTA('Accounts Inventory'!$A$2:$A$25)-COUNTIF('Accounts Inventory'!$L$2:$L$25,"Excluded")
A7: Done | B7: =COUNTIF('Accounts Inventory'!$L$2:$L$25,"Done")
A8: % complete (in scope) | B8: =IFERROR(COUNTIF('Accounts Inventory'!$L$2:$L$25,"Done")/(COUNTA('Accounts Inventory'!$A$2:$A$25)-COUNTIF('Accounts Inventory'!$L$2:$L$25,"Excluded")),0)
A9: P0 items not yet Done | B9: =COUNTIFS('Accounts Inventory'!$J$2:$J$25,"P0",'Accounts Inventory'!$L$2:$L$25,"<>Done")
A10: Open gaps awaiting a decision | B10: =COUNTBLANK('Gaps & Decisions'!$F$4:$F$15)
A12: By Status | B12: Count | C12: % of total
A13: Not Started | B13: =COUNTIF('Accounts Inventory'!$L$2:$L$25,$A$13) | C13: =IFERROR(B13/$B$5,0)
A14: In Progress | B14: =COUNTIF('Accounts Inventory'!$L$2:$L$25,$A$14) | C14: =IFERROR(B14/$B$5,0)
A15: In Review | B15: =COUNTIF('Accounts Inventory'!$L$2:$L$25,$A$15) | C15: =IFERROR(B15/$B$5,0)
A16: Done | B16: =COUNTIF('Accounts Inventory'!$L$2:$L$25,$A$16) | C16: =IFERROR(B16/$B$5,0)
A17: Blocked | B17: =COUNTIF('Accounts Inventory'!$L$2:$L$25,$A$17) | C17: =IFERROR(B17/$B$5,0)
A18: Excluded | B18: =COUNTIF('Accounts Inventory'!$L$2:$L$25,$A$18) | C18: =IFERROR(B18/$B$5,0)
A20: By Traffic Priority | B20: Count | C20: Not Done
A21: P0 | B21: =COUNTIF('Accounts Inventory'!$J$2:$J$25,$A$21) | C21: =COUNTIFS('Accounts Inventory'!$J$2:$J$25,$A$21,'Accounts Inventory'!$L$2:$L$25,"<>Done")
A22: P1 | B22: =COUNTIF('Accounts Inventory'!$J$2:$J$25,$A$22) | C22: =COUNTIFS('Accounts Inventory'!$J$2:$J$25,$A$22,'Accounts Inventory'!$L$2:$L$25,"<>Done")
A23: P2 | B23: =COUNTIF('Accounts Inventory'!$J$2:$J$25,$A$23) | C23: =COUNTIFS('Accounts Inventory'!$J$2:$J$25,$A$23,'Accounts Inventory'!$L$2:$L$25,"<>Done")
A25: By Port Decision | B25: Count
A26: Port as-is | B26: =COUNTIF('Accounts Inventory'!$K$2:$K$25,$A$26)
A27: Redesign | B27: =COUNTIF('Accounts Inventory'!$K$2:$K$25,$A$27)
A28: Drop | B28: =COUNTIF('Accounts Inventory'!$K$2:$K$25,$A$28)
A29: Needs decision | B29: =COUNTIF('Accounts Inventory'!$K$2:$K$25,$A$29)
A31: Legend
A32: Status
A33: Not Started | D33: Inventoried, not begun.
A34: In Progress | D34: Being built on the new shell.
A35: In Review | D35: Built; awaiting parity check against v2.
A36: Done | D36: At capability parity on the new shell, verified against v2.
A37: Blocked | D37: Cannot proceed - reason goes in Notes / Gaps.
A38: Excluded | D38: Deliberately not ported (dead code, or a decision recorded on the Gaps tab).
A40: Traffic Priority
A41: P0 | D41: Top-traffic - sequence these first. The brief says sequence by traffic, not by screen order.
A42: P1 | D42: Regular use.
A43: P2 | D43: Rare or administrative.
A45: Port Decision
A46: Port as-is | D46: Capability and flow are sound; reproduce the capability on the new shell.
A47: Redesign | D47: Capability must survive, the flow must not. Parity is the floor, not the ceiling.
...
